Pig Stack Trace
---------------
ERROR 6000: 
<file q1.pig, line 42, column 0> Output Location Validation Failed for: 'file:///homes/py715/AdvancedDB17CW3/q1 More info to follow:
Output directory file:/homes/py715/AdvancedDB17CW3/q1 already exists

org.apache.pig.impl.plan.VisitorException: ERROR 6000: 
<file q1.pig, line 42, column 0> Output Location Validation Failed for: 'file:///homes/py715/AdvancedDB17CW3/q1 More info to follow:
Output directory file:/homes/py715/AdvancedDB17CW3/q1 already exists
	at org.apache.pig.newplan.logical.rules.InputOutputFileValidator$InputOutputFileVisitor.visit(InputOutputFileValidator.java:95)
	at org.apache.pig.newplan.logical.relational.LOStore.accept(LOStore.java:66)
	at org.apache.pig.newplan.DepthFirstWalker.depthFirst(DepthFirstWalker.java:64)
	at org.apache.pig.newplan.DepthFirstWalker.depthFirst(DepthFirstWalker.java:66)
	at org.apache.pig.newplan.DepthFirstWalker.depthFirst(DepthFirstWalker.java:66)
	at org.apache.pig.newplan.DepthFirstWalker.depthFirst(DepthFirstWalker.java:66)
	at org.apache.pig.newplan.DepthFirstWalker.depthFirst(DepthFirstWalker.java:66)
	at org.apache.pig.newplan.DepthFirstWalker.depthFirst(DepthFirstWalker.java:66)
	at org.apache.pig.newplan.DepthFirstWalker.depthFirst(DepthFirstWalker.java:66)
	at org.apache.pig.newplan.DepthFirstWalker.depthFirst(DepthFirstWalker.java:66)
	at org.apache.pig.newplan.DepthFirstWalker.depthFirst(DepthFirstWalker.java:66)
	at org.apache.pig.newplan.DepthFirstWalker.walk(DepthFirstWalker.java:53)
	at org.apache.pig.newplan.PlanVisitor.visit(PlanVisitor.java:52)
	at org.apache.pig.newplan.logical.rules.InputOutputFileValidator.validate(InputOutputFileValidator.java:45)
	at org.apache.pig.backend.hadoop.executionengine.HExecutionEngine.compile(HExecutionEngine.java:311)
	at org.apache.pig.PigServer.compilePp(PigServer.java:1392)
	at org.apache.pig.PigServer.executeCompiledLogicalPlan(PigServer.java:1317)
	at org.apache.pig.PigServer.execute(PigServer.java:1309)
	at org.apache.pig.PigServer.executeBatch(PigServer.java:387)
	at org.apache.pig.PigServer.executeBatch(PigServer.java:365)
	at org.apache.pig.tools.grunt.GruntParser.executeBatch(GruntParser.java:140)
	at org.apache.pig.tools.grunt.GruntParser.parseStopOnError(GruntParser.java:202)
	at org.apache.pig.tools.grunt.GruntParser.parseStopOnError(GruntParser.java:173)
	at org.apache.pig.tools.grunt.Grunt.exec(Grunt.java:84)
	at org.apache.pig.Main.run(Main.java:613)
	at org.apache.pig.Main.main(Main.java:158)
	at sun.reflect.NativeMethodAccessorImpl.invoke0(Native Method)
	at sun.reflect.NativeMethodAccessorImpl.invoke(NativeMethodAccessorImpl.java:62)
	at sun.reflect.DelegatingMethodAccessorImpl.invoke(DelegatingMethodAccessorImpl.java:43)
	at java.lang.reflect.Method.invoke(Method.java:498)
	at org.apache.hadoop.util.RunJar.run(RunJar.java:221)
	at org.apache.hadoop.util.RunJar.main(RunJar.java:136)
Caused by: org.apache.hadoop.mapred.FileAlreadyExistsException: Output directory file:/homes/py715/AdvancedDB17CW3/q1 already exists
	at org.apache.hadoop.mapreduce.lib.output.FileOutputFormat.checkOutputSpecs(FileOutputFormat.java:146)
	at org.apache.pig.newplan.logical.rules.InputOutputFileValidator$InputOutputFileVisitor.visit(InputOutputFileValidator.java:80)
	... 31 more
================================================================================
